Workbook

Sheet CONFIG
A1: IBM Cybersecurity Services — Quantum Safe Transformation | H1: HOW TO USE THIS SHEET (CONFIG)
A2: CELL TYPE GUIDE: | H2: PURPOSE: | I2: Central configuration sheet. Contains IBM-standard rates, delivery parameters, maturity assessment, and learning curve definitions. All other sheets pull values from here.
A3: IBM Standard — do not modify | H3: WHO FILLS THIS IN: | I3: IBM pre-populates steel-blue cells with standard rates. The ITSO adjusts cream-colored cells to reflect the client's delivery model and organizational maturity.
A4: Client Input — please fill in | H4: DATA FLOW: | I4: CONFIG feeds UNITS (blended rates per unit type, risk %, CG&E %, maturity multiplier, learning curve) and TIMELINE (CG&E %, maturity multiplier)
A5: Calculated — auto-computed
A6: RATE CARD | H6: SECTION: RATE CARD | I6: Hourly/monthly rates for 5 role tiers, split by delivery location (onshore vs offshore). Blended rate is auto-calculated.
A7: Role Tier | B7: Onshore Rate (USD/mo) | C7: Offshore Rate (USD/mo) | D7: Onshore % | E7: Offshore % | F7: Blended Role Rate (USD/mo) | H7: Row | I7: Explanation
A8: Architect / SME | B8: 28000 | C8: 12000 | D8: 0.4 | E8: 0.6 | F8: =B8*D8+C8*E8 | H8: Architect / SME | I8: Senior cryptography experts, solution architects. Highest rate. Used heavily in Discovery, Design, and CMU/PKI work.
A9: Senior Engineer | B9: 24000 | C9: 10000 | D9: 0.35 | E9: 0.65 | F9: =B9*D9+C9*E9 | H9: Senior Engineer | I9: Experienced developers who lead implementation. Core of most unit types.
A10: Developer | B10: 20000 | C10: 8000 | D10: 0.3 | E10: 0.7 | F10: =B10*D10+C10*E10 | H10: Developer | I10: Mid-level developers doing bulk implementation. Dominant role in AMU and DMU.
A11: Tester / QA | B11: 18000 | C11: 7000 | D11: 0.25 | E11: 0.75 | F11: =B11*D11+C11*E11 | H11: Tester / QA | I11: Security testers, pen testers, regression test engineers. Key in Phase 4.
A12: Project Manager | B12: 26000 | C12: 11000 | D12: 0.4 | E12: 0.6 | F12: =B12*D12+C12*E12 | H12: Project Manager | I12: Engagement/delivery managers. Higher proportion in governance-heavy units (FAU, VTU).
H13: FORMULA: | I13: Blended Role Rate = (Onshore Rate x Onshore %) + (Offshore Rate x Offshore %) Example: Architect = ($28,000 x 40%) + ($12,000 x 60%) = $18,400/mo
A14: BLENDED RATE BY UNIT TYPE | H14: SECTION: BLENDED RATE BY UNIT | I14: Each unit type has a different role mix. FAU is governance-heavy (more PM, Architect). AMU is implementation-heavy (more Developers). The blended unit rate = role mix x role rates.
A15: Unit Type | B15: Architect % | C15: Sr Engineer % | D15: Developer % | E15: Tester % | F15: PM % | G15: Blended Unit Rate (USD/mo) | H15: Row | I15: Explanation
A16: FAU | B16: 0.2 | C16: 0.3 | D16: 0.2 | E16: 0.1 | F16: 0.2 | G16: =B16*$F$8+C16*$F$9+D16*$F$10+E16*$F$11+F16*$F$12 | H16: FAU | I16: Governance-focused: 20% Arch, 30% Sr, 20% Dev, 10% Test, 20% PM. High PM/Arch mix for cross-unit coordination.
A17: NMU | B17: 0.15 | C17: 0.25 | D17: 0.35 | E17: 0.15 | F17: 0.1 | G17: =B17*$F$8+C17*$F$9+D17*$F$10+E17*$F$11+F17*$F$12 | H17: NMU | I17: Network/infra: 15% Arch, 25% Sr, 35% Dev, 15% Test, 10% PM. Developer-heavy for config automation.
A18: AMU | B18: 0.1 | C18: 0.2 | D18: 0.4 | E18: 0.2 | F18: 0.1 | G18: =B18*$F$8+C18*$F$9+D18*$F$10+E18*$F$11+F18*$F$12 | H18: AMU | I18: Largest unit (8000 apps): 10% Arch, 20% Sr, 40% Dev, 20% Test, 10% PM. Factory model.
A19: PMU | B19: 0.15 | C19: 0.25 | D19: 0.3 | E19: 0.2 | F19: 0.1 | G19: =B19*$F$8+C19*$F$9+D19*$F$10+E19*$F$11+F19*$F$12 | H19: PMU | I19: Platform/cloud: 15% Arch, 25% Sr, 30% Dev, 20% Test, 10% PM.
A20: CMU | B20: 0.2 | C20: 0.3 | D20: 0.25 | E20: 0.1 | F20: 0.15 | G20: =B20*$F$8+C20*$F$9+D20*$F$10+E20*$F$11+F20*$F$12 | H20: CMU | I20: Specialist-heavy: 20% Arch, 30% Sr, 25% Dev, 10% Test, 15% PM. Highest architect mix for PKI complexity.
A21: DMU | B21: 0.1 | C21: 0.2 | D21: 0.4 | E21: 0.2 | F21: 0.1 | G21: =B21*$F$8+C21*$F$9+D21*$F$10+E21*$F$11+F21*$F$12 | H21: DMU | I21: Data migration: Same as AMU mix.
A22: DAU | B22: 0.1 | C22: 0.25 | D22: 0.4 | E22: 0.15 | F22: 0.1 | G22: =B22*$F$8+C22*$F$9+D22*$F$10+E22*$F$11+F22*$F$12 | H22: DAU | I22: Pipeline/tooling: 10% Arch, 25% Sr, 40% Dev, 15% Test, 10% PM.
A23: VTU | B23: 0.05 | C23: 0.15 | D23: 0.15 | E23: 0.05 | F23: 0.6 | G23: =B23*$F$8+C23*$F$9+D23*$F$10+E23*$F$11+F23*$F$12 | H23: VTU | I23: Vendor management: 5% Arch, 15% Sr, 15% Dev, 5% Test, 60% PM. Highest PM mix for coordination work.
H24: FORMULA: | I24: Blended Unit Rate = (Arch% x Arch Rate) + (Sr% x Sr Rate) + (Dev% x Dev Rate) + (Test% x Test Rate) + (PM% x PM Rate)
A25: GLOBAL PARAMETERS | H25: SECTION: GLOBAL PARAMETERS | I25: Program-wide settings that affect all cost calculations.
A26: Working Days per Month | B26: 20 | H26: Working Days/Month | I26: Standard = 20. Used for converting FTE-months to mandays if needed.
A27: Risk Contingency % | B27: 0.2 | H27: Risk Contingency % | I27: Default 20%. Applied to each unit's subtotal. Industry standard 15-25% for ROM-stage estimates.
A28: CG&E (Central Governance & Enablement) % | B28: 0.1 | H28: CG&E % | I28: Default 10%. Covers: PMO, governance board, enterprise architecture oversight, compliance, training.
A30: MATURITY ASSESSMENT (PQC Readiness) | H30: SECTION: MATURITY ASSESSMENT | I30: Based on PKI Consortium PQC Maturity Model (PQCMM). Lower maturity = higher cost.
A31: Dimension | B31: Score (1-5) | C31: Guidance | H31: How to score: | I31: Score each dimension 1-5 based on current client state. Be honest — overestimating maturity leads to underestimating costs.
A32: Cryptographic Inventory & Visibility | B32: 3 | C32: 1=None, 3=Partial CMDB, 5=Full CBOM | H32: Crypto Inventory | I32: Does the client know what crypto they use? 1=No inventory. 3=Partial CMDB. 5=Full CBOM with automated discovery.
A33: Governance & Policy Maturity | B33: 3 | C33: 1=Ad-hoc, 3=Defined policies, 5=Enforced & audited | H33: Governance & Policy | I33: Are there crypto policies? 1=Ad-hoc. 3=Written policies, some enforcement. 5=Policies enforced via automation.
A34: Automation & Tooling Readiness | B34: 2 | C34: 1=Manual, 3=Some automation, 5=Full CI/CD crypto checks | H34: Automation & Tooling | I34: How automated is crypto management? 1=Manual. 3=Some automation. 5=Full CI/CD with crypto checks.
A35: Skills & Organizational Readiness | B35: 3 | C35: 1=No PQC awareness, 3=Some training, 5=Dedicated team | H35: Skills & Readiness | I35: Does the org understand PQC? 1=No awareness. 3=Some training. 5=Dedicated PQC team, funded program.
A36: Architecture Modernization | B36: 2 | C36: 1=Monolith/legacy, 3=Mixed, 5=Cloud-native/modular | H36: Architecture | I36: How modern is the stack? 1=Monoliths/mainframes. 3=Mixed. 5=Cloud-native, microservices, modular.
A37: Average Maturity Score | B37: =AVERAGE(B32:B36) | H37: Average Score | I37: Simple average of the 5 dimension scores.
A38: Maturity Multiplier | B38: =IF(B37<=1.5,1.25,IF(B37<=2.5,1.15,IF(B37<=3.5,1.0,IF(B37<=4.5,0.9,0.85)))) | C38: 1.25=Immature, 1.0=Moderate, 0.85=Excellent | H38: Maturity Multiplier | I38: Maps average to cost multiplier: 1.0-1.5 = 1.25x (25% uplift) 1.6-2.5 = 1.15x (15% uplift) 2.6-3.5 = 1.00x (baseline) 3.6-4.5 = 0.90x (10% discount) 4.6-5.0 = 0.85x (15% discount)
A40: LEARNING CURVE (AMU) | H40: SECTION: LEARNING CURVE (AMU) | I40: Based on Wright's Law. As more apps are migrated, per-app cost drops from reuse, automation, and institutional knowledge.
A41: Wave | B41: App Range | C41: Cost Multiplier | H41: How it works: | I41: 8000 apps are migrated in waves. Each wave gets a cost multiplier. The blended average determines effective per-app cost reduction.
A42: Pathfinder | B42: 1 - 50 | C42: 1.5 | H42: Wave 1: Pathfinder (1-50) | I42: 1.5x. First 50 apps are expensive: building tooling, playbooks, training teams.
...

Sheet INPUT
A1: IBM Cybersecurity Services — Client Environment Profile | H1: STEP-BY-STEP GUIDE
A2: CELL TYPE GUIDE: | H2: PURPOSE: Your inputs here drive ALL cost calculations across the workbook.
A3: IBM Standard — do not modify | H3: STEPS: 1. Enter Client Name and Engagement ID 2. Score each Complexity Factor (1-3) 3. Enter Unit Counts from your discovery 4. Distribute total applications across archetypes 5. Verify the archetype total matches (Validation = 'OK')
A4: Client Input — please fill in
A5: Calculated — auto-computed
A6: BASE INFORMATION
A7: Client Name
A8: Engagement ID
A10: COMPLEXITY ASSESSMENT | H10: SECTION: COMPLEXITY ASSESSMENT
A11: Factor | B11: Score (1-3) | C11: 1 = Low | D11: 2 = Medium | E11: 3 = High | F11: Weight | G11: Weighted Score | H11: Each factor scored 1 (Low), 2 (Medium), 3 (High). Multiplied by Weight to produce Weighted Score. Composite multiplier ranges 1.0x to 2.0x.
A12: Crypto Usage | B12: 1 | C12: TLS only, libraries abstracted | D12: Mix of TLS + embedded, some custom | E12: Deep custom crypto, HSM, PKI-embedded | F12: 0.25 | G12: =B12*F12 | H12: Crypto Usage: How deeply is cryptography embedded? TLS only via libraries = 1. Custom encryption + HSM integrations = 3.
A13: Dependencies | B13: 1 | C13: Self-contained, few integrations | D13: 5-15 dependent systems | E13: 15+ systems, cross-org | F13: 0.2 | G13: =B13*F13 | H13: Dependencies: How many external systems connect? Self-contained = 1. 15+ systems with cross-org flows = 3.
A14: Architecture Type | B14: 1 | C14: Cloud-native, modular | D14: Mixed modern/legacy | E14: Monolith, mainframe, tightly coupled | F14: 0.25 | G14: =B14*F14 | H14: Architecture: Cloud-native microservices = 1. Mixed = 2. Monolithic mainframe = 3.
A15: Change Readiness | B15: 1 | C15: CI/CD, automated tests | D15: Semi-automated, manual gates | E15: Manual deployment, limited tests | F15: 0.15 | G15: =B15*F15 | H15: Change Readiness: Full CI/CD = 1. Semi-automated = 2. Manual deployment = 3.
A16: Urgency | B16: 1 | C16: Planned, flexible timeline | D16: Regulatory deadline within 2 years | E16: Immediate, compliance-critical | F16: 0.15 | G16: =B16*F16 | H16: Urgency: Flexible timeline = 1. Regulatory deadline in 2 years = 2. Immediate compliance = 3.
A17: Composite Complexity Multiplier | G17: =0.5+SUM(G12:G16)*0.5 | H17: FORMULA: Multiplier = 0.5 + (Sum of Weighted Scores) x 0.5 All Low: 1.00 x 0.5 + 0.5 = 1.0x All High: 3.00 x 0.5 + 0.5 = 2.0x
A18: (Range: 1.0x at all-Low to 2.0x at all-High)
A20: UNIT COUNT QUESTIONS | H20: SECTION: UNIT COUNT QUESTIONS
A21: Question | B21: Count | H21: These counts drive unit sizing on the UNITS sheet. Each question maps to one of 8 unit types:
A22: Number of independently governed delivery units (BUs, entities, geos) with own dev/release authority | B22: 22 | H22: Maps to FAU. Count BUs, legal entities, or regions that independently manage crypto policies.
A23: Number of distinct network trust domains or connectivity zones | B23: 10 | H23: Maps to NMU. Count distinct network zones or trust domains with independent TLS/IPsec/VPN.
A24: Total number of applications (all types) | B24: 8000 | H24: Maps to AMU. Total app count — the single biggest cost driver. Include all apps using any cryptography.
A25: Number of distinct runtime platforms (cloud accounts, on-prem, containers, mainframe) | B25: 20 | H25: Maps to PMU. Count runtime platforms: cloud subscriptions, on-prem clusters, container platforms, LPARs.
A26: Number of PKI/KMS domains that need to be transformed | B26: 20 | H26: Maps to CMU. Count PKI hierarchies and KMS instances needing quantum-safe migration.
A27: Number of data store classes requiring cryptographic control | B27: 80 | H27: Maps to DMU. Count data store classes by encryption type: databases, object stores, backup, archival.
A28: Number of CI/CD pipelines or deployment paths handling crypto material | B28: 10 | H28: Maps to DAU. Count CI/CD pipelines that create, rotate, or validate cryptographic material.
A29: Number of vendor/SaaS products where crypto is externally controlled | B29: 250 | H29: Maps to VTU. Count vendor products where crypto is externally controlled (SaaS, contracted services).
A31: APPLICATION ARCHETYPE DISTRIBUTION | H31: SECTION: ARCHETYPE DISTRIBUTION
A32: Archetype | B32: Count | C32: % of Total | H32: Break down total apps into 6 categories. This determines weighted average effort per app on ESTIMATE sheet.
A33: Simple Web App / API Service | B33: 3200 | C33: =B33/$B$24 | H33: Simple Web App (0.9 FTE-mo): Standard TLS. Minimal crypto surface. Easiest to migrate.
A34: Mainframe / Legacy System | B34: 800 | C34: =B34/$B$24 | H34: Mainframe (4.0 FTE-mo): COBOL/JCL with embedded crypto. Specialist skills required. Most expensive per app.
A35: ERP / Packaged Application | B35: 600 | C35: =B35/$B$24 | H35: ERP / Packaged (3.0 FTE-mo): SAP, Oracle. Effort is in vendor coordination + config.
A36: Mobile Application | B36: 400 | C36: =B36/$B$24 | H36: Mobile (1.0 FTE-mo): iOS/Android. Mostly TLS + cert pinning. Moderate effort.
A37: Microservice / Cloud-Native | B37: 2200 | C37: =B37/$B$24 | H37: Microservice (0.6 FTE-mo): Cloud-native, containerized. Cheapest to migrate.
A38: Monolith / Legacy Custom | B38: 800 | C38: =B38/$B$24 | H38: Monolith (3.5 FTE-mo): Large custom apps with hardcoded crypto. High effort.
A39: Total | B39: =SUM(B33:B38) | C39: =SUM(C33:C38) | H39: Counts MUST sum to total applications. Check Validation row.
A40: Validation | B40: =IF(B39=B24,"OK","MISMATCH - must equal total apps!")

Sheet ESTIMATE
A1: IBM Cybersecurity Services — Per-Application Effort Estimator | H1: HOW THIS SHEET WORKS
H2: PURPOSE: Calculates weighted average effort per application, considering archetype mix and complexity. Output (cell E32) feeds AMU on UNITS sheet.
A3: PHASE EFFORT DISTRIBUTION | H3: DATA FLOW: Receives: Complexity Multiplier from INPUT!G17, Archetype counts from INPUT!B33:B38 Produces: Weighted Average Effort (E32) for UNITS sheet
A4: Phase | B4: 1: Discovery (15%) | C4: 2: Design (10%) | D4: 3: Development (45%) | E4: 4: Testing (20%) | F4: 5: Deployment (10%) | G4: Total
A6: BASE EFFORT BY ARCHETYPE (FTE-months per app, before complexity) | H6: SECTION: BASE EFFORT BY ARCHETYPE
A7: Archetype | B7: 1: Discovery (15%) | C7: 2: Design (10%) | D7: 3: Development (45%) | E7: 4: Testing (20%) | F7: 5: Deployment (10%) | G7: Total | H7: IBM-standard effort (FTE-months) to migrate one app of each type through all 5 phases. Phase split: Discovery 15%, Design 10%, Development 45%, Testing 20%, Deployment 10%.
A8: Simple Web App / API Service | B8: 0.135 | C8: 0.09 | D8: 0.405 | E8: 0.18 | F8: 0.09 | G8: =SUM(B8:F8)
A9: Mainframe / Legacy System | B9: 0.6 | C9: 0.4 | D9: 1.8 | E9: 0.8 | F9: 0.4 | G9: =SUM(B9:F9)
A10: ERP / Packaged Application | B10: 0.45 | C10: 0.3 | D10: 1.35 | E10: 0.6 | F10: 0.3 | G10: =SUM(B10:F10)
A11: Mobile Application | B11: 0.15 | C11: 0.1 | D11: 0.45 | E11: 0.2 | F11: 0.1 | G11: =SUM(B11:F11)
A12: Microservice / Cloud-Native | B12: 0.09 | C12: 0.06 | D12: 0.27 | E12: 0.12 | F12: 0.06 | G12: =SUM(B12:F12)
A13: Monolith / Legacy Custom | B13: 0.525 | C13: 0.35 | D13: 1.575 | E13: 0.7 | F13: 0.35 | G13: =SUM(B13:F13)
A15: COMPLEXITY-ADJUSTED EFFORT | H15: SECTION: COMPLEXITY-ADJUSTED EFFORT
A16: Complexity Multiplier (from INPUT) | B16: =INPUT!G17 | H16: Complexity Multiplier applied to every archetype. Formula: Adjusted = Base x Multiplier All Low (1.0x): Simple Web App = 0.9 x 1.0 = 0.9 All Med (1.5x): Simple Web App = 0.9 x 1.5 = 1.35
A17: Simple Web App / API Service (adjusted) | B17: =B8*$B$16 | C17: =C8*$B$16 | D17: =D8*$B$16 | E17: =E8*$B$16 | F17: =F8*$B$16 | G17: =SUM(B17:F17)
A18: Mainframe / Legacy System (adjusted) | B18: =B9*$B$16 | C18: =C9*$B$16 | D18: =D9*$B$16 | E18: =E9*$B$16 | F18: =F9*$B$16 | G18: =SUM(B18:F18)
A19: ERP / Packaged Application (adjusted) | B19: =B10*$B$16 | C19: =C10*$B$16 | D19: =D10*$B$16 | E19: =E10*$B$16 | F19: =F10*$B$16 | G19: =SUM(B19:F19)
A20: Mobile Application (adjusted) | B20: =B11*$B$16 | C20: =C11*$B$16 | D20: =D11*$B$16 | E20: =E11*$B$16 | F20: =F11*$B$16 | G20: =SUM(B20:F20)
A21: Microservice / Cloud-Native (adjusted) | B21: =B12*$B$16 | C21: =C12*$B$16 | D21: =D12*$B$16 | E21: =E12*$B$16 | F21: =F12*$B$16 | G21: =SUM(B21:F21)
A22: Monolith / Legacy Custom (adjusted) | B22: =B13*$B$16 | C22: =C13*$B$16 | D22: =D13*$B$16 | E22: =E13*$B$16 | F22: =F13*$B$16 | G22: =SUM(B22:F22)
A24: WEIGHTED AVERAGE EFFORT (feeds AMU on UNITS sheet) | H24: SECTION: WEIGHTED AVERAGE EFFORT
A25: Archetype | B25: App Count | C25: % of Total | D25: Adj Effort/App | E25: Weighted Contribution | H25: Combines all archetypes into single average effort, weighted by app count. Formula: Weighted Avg = SUM(each archetype's % x adjusted effort)
A26: Simple Web App / API Service | B26: =INPUT!B33 | C26: =B26/SUM($B$26:$B$31) | D26: =G17 | E26: =C26*D26
A27: Mainframe / Legacy System | B27: =INPUT!B34 | C27: =B27/SUM($B$26:$B$31) | D27: =G18 | E27: =C27*D27
A28: ERP / Packaged Application | B28: =INPUT!B35 | C28: =B28/SUM($B$26:$B$31) | D28: =G19 | E28: =C28*D28
A29: Mobile Application | B29: =INPUT!B36 | C29: =B29/SUM($B$26:$B$31) | D29: =G20 | E29: =C29*D29
A30: Microservice / Cloud-Native | B30: =INPUT!B37 | C30: =B30/SUM($B$26:$B$31) | D30: =G21 | E30: =C30*D30
A31: Monolith / Legacy Custom | B31: =INPUT!B38 | C31: =B31/SUM($B$26:$B$31) | D31: =G22 | E31: =C31*D31
A32: Weighted Avg Effort per App (FTE-months) | E32: =SUM(E26:E31)
A34: WORKED EXAMPLE: Computing Weighted Average (with default values)
A35: Archetype | B35: Count | C35: % of Total | D35: Effort/App | E35: Contribution | H35: Calculation Detail
A36: Simple Web App | B36: 3,200 | C36: 40.0% | D36: 0.90 | E36: 0.3600 | H36: 3200/8000 = 40% x 0.90 = 0.3600
A37: Mainframe | B37: 800 | C37: 10.0% | D37: 4.00 | E37: 0.4000 | H37: 800/8000 = 10% x 4.00 = 0.4000
A38: ERP / Packaged | B38: 600 | C38: 7.5% | D38: 3.00 | E38: 0.2250 | H38: 600/8000 = 7.5% x 3.00 = 0.2250
A39: Mobile | B39: 400 | C39: 5.0% | D39: 1.00 | E39: 0.0500 | H39: 400/8000 = 5% x 1.00 = 0.0500
A40: Microservice | B40: 2,200 | C40: 27.5% | D40: 0.60 | E40: 0.1650 | H40: 2200/8000 = 27.5% x 0.60 = 0.1650
A41: Monolith/Legacy | B41: 800 | C41: 10.0% | D41: 3.50 | E41: 0.3500 | H41: 800/8000 = 10% x 3.50 = 0.3500
A42: TOTAL | B42: 8,000 | C42: 100% | E42: 1.5500 | H42: Sum = 0.36 + 0.40 + 0.225 + 0.05 + 0.165 + 0.35 = 1.55 FTE-months/app
A44: This 1.55 FTE-months/app feeds into UNITS sheet as AMU base effort.
A45: On UNITS: AMU Small = 1.55 x 1.0 = 1.55 | Medium = 1.55 x 2.0 = 3.10 | Large = 1.55 x 4.0 = 6.20

Sheet UNITS
A1: IBM Cybersecurity Services — Enterprise Cost Model | AB1: ROW-BY-ROW FORMULA GUIDE
A2: Units | B2: Federated Adoption Unit (FAU) | E2: Network / Connectivity Migration Unit (NMU) | H2: Application Migration Unit (AMU) | K2: Platform/Cloud/Runtime Migration Unit (PMU) | N2: PKI/CLM/KMS Migration Unit (CMU) | Q2: Data & Storage Migration Unit (DMU) | T2: DevSecOps & Automation Unit (DAU) | W2: Vendor / Third-Party Unit (VTU) | Z2: Totals | AB2: Row 2: UNIT TYPE HEADERS — 8 unit types, each with Small/Medium/Large (3 cols per unit, 24 value columns total).
A3: Estimated Units | B3: =INPUT!B22 | E3: =INPUT!B23 | H3: =INPUT!B24 | K3: =INPUT!B25 | N3: =INPUT!B26 | Q3: =INPUT!B27 | T3: =INPUT!B28 | W3: =INPUT!B29 | AB3: Row 3: ESTIMATED UNITS — Pulled from INPUT sheet. Total number of units to be migrated.
B4: Key Activities: - Roll out central QS policies, standards, and patterns to local units - Act as first-line decision and exception handling point - Support local discovery, reporting, and risk visibility - Coordinate vendors and delivery teams within the unit - Feed local constraints and risks back to central governance Size definitions: - Small: Homogeneous tech stack, low regulatory variation - Medium: Mixed platforms, moderate regulatory requirements - Large: Diverse platforms, strong regulatory pressure | E4: Key Activities: - Endpoint & Protocol Mapping: Identify TLS, VPN, IPsec usage - Standardization & Design: Define cipher suites, TLS versions - Implementation & Automation: Update configs, automate cert lifecycle - Migration & Stabilization: Phase changes, resolve production issues Size definitions: - Small: Single network tier, automated certificate handling - Medium: Regional infrastructure, partial automation, legacy protocols - Large: Global/legacy network, manual lifecycle, high outage risk | H4: Key Activities: - Discovery & Planning: Identify cryptographic usage and exposure - Design & Pattern Selection: Choose approved algos, libraries - Refactor & Implementation: Replace hard-coded crypto, update configs - Test, Deploy, Stabilize: Validate functionality and integrations Size definitions: - Small: Standard libraries, minimal crypto, limited integrations - Medium: Mix of standard and embedded crypto, several dependencies - Large: Custom/hardcoded crypto in business-critical legacy code | K4: Key Activities: - Platform Crypto Assessment: Review defaults, gaps, workloads - Baseline & Architecture Design: Define hardened crypto configs - Configuration & Integration: Update platform settings, key/certs - Rollout & Validation: Rolling updates, stabilize runtime Size definitions: - Small: Cloud-native platform, default crypto configs - Medium: Shared platform, custom crypto, partial HSM integration - Large: Hybrid/bespoke runtime, inconsistent controls, high blast radius | N4: Key Activities: - Establish crypto-agile trust foundations (CAs, trust anchors) - Automate cert issuance, rotation, revocation across environments - Migrate to quantum-safe algorithms in PKI and KMS - Standardize key generation, storage, rotation (HSMs, KMS) - Integrate PKI/KMS with apps, platforms, networks, DevSecOps Size definitions: - Small: One PKI/KMS instance, limited consumers - Medium: 2-3 PKIs/KMS domains, shared services - Large: Enterprise-wide PKI/KMS, complex trust chains | Q4: Key Activities: - Data & Risk Assessment: Identify long-lived, sensitive datasets - Encryption Strategy Design: Define re-encryption, key lifecycle - Implementation & Re-Encryption: Apply crypto changes, migrate data - Validation & Stabilization: Confirm integrity, access, recovery Size definitions: - Small: Managed storage, built-in encryption, limited re-encryption - Medium: Shared enterprise data, regulated data, custom key handling - Large: High-volume, long-retention store, crypto changes impact availability | T4: Key Activities: - Pipeline Crypto Mapping: Identify crypto controls and gaps in CI/CD - Policy & Control Design: Define validation rules, enforcement levels - Integration & Rollout: Embed checks into pipelines and workflows - Tuning & Enablement: Reduce noise, support developer adoption Size definitions: - Small: Single CI/CD pipeline, standard tooling - Medium: Shared pipelines, policy tuning, exception handling - Large: Federated DevOps, many pipelines, high enforcement risk | W4: Key Activities: - Dependency Identification: Identify crypto reliance and criticality - Requirement Definition: Define PQC and crypto expectations - Vendor Engagement: Validate roadmaps and remediation plans - Tracking & Exception Handling: Monitor progress, manage residual risk Size definitions: - Small: Low-risk, replaceable vendor, minimal crypto dependency - Medium: Core vendor, partial visibility, negotiable roadmap - Large: Deeply embedded/regulated vendor, limited leverage | AB4: Row 4: KEY ACTIVITIES — What each unit does and how Small/Medium/Large are defined.
A5: Unit | B5: Per governed domains / BUs / geos | E5: Per network / connectivity domain | H5: Per application | K5: Per platform / cloud / runtime | N5: Per PKI / CLM / KMS domain | Q5: Per data & storage class | T5: Per DevSecOps pipeline | W5: Per vendor third-party | AB5: Row 5: PER-UNIT LABEL — What each unit represents (e.g., 'Per application' for AMU).
A6: Sizing | B6: Small | C6: Medium | D6: Large | E6: Small | F6: Medium | G6: Large | H6: Small | I6: Medium | J6: Large | K6: Small | L6: Medium | M6: Large | N6: Small | O6: Medium | P6: Large | Q6: Small | R6: Medium | S6: Large | T6: Small | U6: Medium | V6: Large | W6: Small | X6: Medium | Y6: Large | AB6: Row 6: SIZING — Small, Medium, Large. Complexity within each unit type.
A7: Unit % Split per complexity | B7: 0.55 | C7: 0.3 | D7: 0.15 | E7: 0.55 | F7: 0.3 | G7: 0.15 | H7: 0.55 | I7: 0.25 | J7: 0.2 | K7: 0.45 | L7: 0.3 | M7: 0.25 | N7: 0.3 | O7: 0.5 | P7: 0.2 | Q7: 0.6 | R7: 0.25 | S7: 0.15 | T7: 0.45 | U7: 0.4 | V7: 0.15 | W7: 0.7 | X7: 0.2 | Y7: 0.1 | AB7: Row 7: UNIT % SPLIT — Client-editable. % of units that are S/M/L. Must sum to 100%. Example: AMU 55/25/20 means 55% of 8000 apps = 4400 are 'Small'.
A8: Unit Count | B8: =B3*B7 | C8: =B3*C7 | D8: =B3*D7 | E8: =E3*E7 | F8: =E3*F7 | G8: =E3*G7 | H8: =H3*H7 | I8: =H3*I7 | J8: =H3*J7 | K8: =K3*K7 | L8: =K3*L7 | M8: =K3*M7 | N8: =N3*N7 | O8: =N3*O7 | P8: =N3*P7 | Q8: =Q3*Q7 | R8: =Q3*R7 | S8: =Q3*S7 | T8: =T3*T7 | U8: =T3*U7 | V8: =T3*V7 | W8: =W3*W7 | X8: =W3*X7 | Y8: =W3*Y7 | AB8: Row 8: UNIT COUNT = Estimated Units x Unit % Split. Example: FAU Small = 22 x 55% = 12.1 units.
A9: Base Effort (FTE-months) | B9: 2 | C9: 4 | D9: 6 | E9: 1 | F9: 3 | G9: 6 | H9: =ESTIMATE!E32*1.0 | I9: =ESTIMATE!E32*2.0 | J9: =ESTIMATE!E32*4.0 | K9: 2 | L9: 4 | M9: 8 | N9: 2 | O9: 5 | P9: 9 | Q9: 1 | R9: 2 | S9: 5 | T9: 1 | U9: 2 | V9: 4 | W9: 0.5 | X9: 1.5 | Y9: 3 | AB9: Row 9: BASE EFFORT (FTE-months) per unit. Most units: IBM-standard value. AMU: Auto-calculated from ESTIMATE!E32 x size multiplier (1.0/2.0/4.0).
A10: Learning Curve Factor | B10: 1 | C10: 1 | D10: 1 | E10: 1 | F10: 1 | G10: 1 | H10: =(MIN(50,INPUT!B24)*CONFIG!C42+MIN(150,MAX(0,INPUT!B24-50))*CONFIG!C43+MIN(800,MAX(0,INPUT!B24-200))*CONFIG!C44+MIN(3000,MAX(0,INPUT!B24-1000))*CONFIG!C45+MAX(0,INPUT!B24-4000)*CONFIG!C46)/INPUT!B24 | I10: =(MIN(50,INPUT!B24)*CONFIG!C42+MIN(150,MAX(0,INPUT!B24-50))*CONFIG!C43+MIN(800,MAX(0,INPUT!B24-200))*CONFIG!C44+MIN(3000,MAX(0,INPUT!B24-1000))*CONFIG!C45+MAX(0,INPUT!B24-4000)*CONFIG!C46)/INPUT!B24 | J10: =(MIN(50,INPUT!B24)*CONFIG!C42+MIN(150,MAX(0,INPUT!B24-50))*CONFIG!C43+MIN(800,MAX(0,INPUT!B24-200))*CONFIG!C44+MIN(3000,MAX(0,INPUT!B24-1000))*CONFIG!C45+MAX(0,INPUT!B24-4000)*CONFIG!C46)/INPUT!B24 | K10: 1 | L10: 1 | M10: 1 | N10: 1 | O10: 1 | P10: 1 | Q10: 1 | R10: 1 | S10: 1 | T10: 1 | U10: 1 | V10: 1 | W10: 1 | X10: 1 | Y10: 1 | AB10: Row 10: LEARNING CURVE FACTOR — Only AMU (value <1). All others = 1.0. With 8000 apps: factor = 0.4119 (~41% of baseline cost).
A11: Effective Effort per Unit | B11: =B9*B10 | C11: =C9*C10 | D11: =D9*D10 | E11: =E9*E10 | F11: =F9*F10 | G11: =G9*G10 | H11: =H9*H10 | I11: =I9*I10 | ... Y11: =Y9*Y10 | AB11: Row 11: EFFECTIVE EFFORT = Base Effort x Learning Curve Factor.
A12: Total Effort (FTE-months) | B12: =B8*B11 | C12: =C8*C11 | D12: =D8*D11 | E12: =E8*E11 | F12: =F8*F11 | G12: =G8*G11 | H12: =H8*H11 | I12: =I8*I11 | ... Y12: =Y8*Y11 | AB12: Row 12: TOTAL EFFORT = Unit Count x Effective Effort. Example: AMU Small = 4400 x 0.638 = 2,807 FTE-months.
A13: Blended FTE-Month Rate (USD) | B13: =CONFIG!G16 | C13: =CONFIG!G16 | D13: =CONFIG!G16 | E13: =CONFIG!G17 | F13: =CONFIG!G17 | G13: =CONFIG!G17 | H13: =CONFIG!G18 | I13: =CONFIG!G18 | J13: =CONFIG!G18 | K13: =CONFIG!G19 | L13: =CONFIG!G19 | M13: =CONFIG!G19 | N13: =CONFIG!G20 | O13: =CONFIG!G20 | P13: =CONFIG!G20 | Q13: =CONFIG!G21 | R13: =CONFIG!G21 | S13: =CONFIG!G21 | T13: =CONFIG!G22 | U13: =CONFIG!G22 | V13: =CONFIG!G22 | W13: =CONFIG!G23 | X13: =CONFIG!G23 | Y13: =CONFIG!G23 | AB13: Row 13: BLENDED FTE-MONTH RATE from CONFIG per unit type.
A14: Unit Labour Cost (USD) | B14: =B11*B13 | C14: =C11*C13 | D14: =D11*D13 | E14: =E11*E13 | F14: =F11*F13 | G14: =G11*G13 | H14: =H11*H13 | I14: =I11*I13 | ... Y14: =Y11*Y13 | AB14: Row 14: UNIT LABOUR COST = Effective Effort x Blended Rate.
A15: Labour Cost (USD) | B15: =B8*B14 | C15: =C8*C14 | D15: =D8*D14 | E15: =E8*E14 | F15: =F8*F14 | G15: =G8*G14 | H15: =H8*H14 | I15: =I8*I14 | ... Y15: =Y8*Y14 | AB15: Row 15: LABOUR COST = Unit Count x Unit Labour Cost.
A16: Tooling / Tech Overhead % | B16: 0 | C16: 0 | D16: 0 | E16: 0.1 | F16: 0.1 | G16: 0.1 | H16: 0.15 | I16: 0.15 | J16: 0.15 | K16: 0.08 | L16: 0.08 | M16: 0.08 | N16: 0.2 | O16: 0.2 | P16: 0.2 | Q16: 0.12 | R16: 0.12 | S16: 0.12 | T16: 0 | U16: 0 | V16: 0 | W16: 0.05 | X16: 0.05 | Y16: 0.05 | AB16: Row 16: TOOLING % — IBM-standard. Varies: 0% FAU/DAU, 8% PMU, 10% NMU, 12% DMU, 15% AMU, 20% CMU, 5% VTU.
A17: Tooling Overhead Cost (USD) | B17: =B15*B16 | C17: =C15*C16 | D17: =D15*D16 | E17: =E15*E16 | F17: =F15*F16 | G17: =G15*G16 | H17: =H15*H16 | I17: =I15*I16 | ... Y17: =Y15*Y16 | AB17: Row 17: TOOLING COST = Labour Cost x Tooling %.
A18: Subtotal | B18: =B15+B17 | C18: =C15+C17 | D18: =D15+D17 | E18: =E15+E17 | F18: =F15+F17 | G18: =G15+G17 | H18: =H15+H17 | I18: =I15+I17 | ... Y18: =Y15+Y17 | AB18: Row 18: SUBTOTAL = Labour + Tooling.
A19: Risk Contingency % | B19: =CONFIG!B27 | C19: =CONFIG!B27 | D19: =CONFIG!B27 | E19: =CONFIG!B27 | F19: =CONFIG!B27 | G19: =CONFIG!B27 | H19: =CONFIG!B27 | I19: =CONFIG!B27 | J19: =CONFIG!B27 | K19: =CONFIG!B27 | L19: =CONFIG!B27 | M19: =CONFIG!B27 | N19: =CONFIG!B27 | O19: =CONFIG!B27 | P19: =CONFIG!B27 | Q19: =CONFIG!B27 | R19: =CONFIG!B27 | S19: =CONFIG!B27 | T19: =CONFIG!B27 | U19: =CONFIG!B27 | V19: =CONFIG!B27 | W19: =CONFIG!B27 | X19: =CONFIG!B27 | Y19: =CONFIG!B27 | AB19: Row 19: RISK % from CONFIG. Default 20%. Covers unknowns.
A20: Risk Contingency Cost (USD) | B20: =B18*B19 | C20: =C18*C19 | D20: =D18*D19 | E20: =E18*E19 | F20: =F18*F19 | G20: =G18*G19 | H20: =H18*H19 | I20: =I18*I19 | ... Y20: =Y18*Y19 | AB20: Row 20: RISK COST = Subtotal x Risk %.
A21: UNIT TOTALS | B21: =B18+B20 | C21: =C18+C20 | D21: =D18+D20 | E21: =E18+E20 | F21: =F18+F20 | G21: =G18+G20 | H21: =H18+H20 | I21: =I18+I20 | ... Y21: =Y18+Y20 | AB21: Row 21: UNIT TOTALS = Subtotal + Risk.
A23: Grand Total (all units) | Z23: =B21+C21+D21+E21+F21+G21+H21+I21+J21+K21+L21+M21+N21+O21+P21+Q21+R21+S21+T21+U21+V21+W21+X21+Y21 | AB23: Row 23: GRAND TOTAL (col Z) = Sum of all 24 unit total cells.
A24: Central Governance & Enablement | Z24: =Z23*CONFIG!B28 | AB24: Row 24: CG&E = Grand Total x 10%. Covers PMO, governance, training.
A25: Maturity Adjustment | Z25: =Z23*(CONFIG!B38-1) | AB25: Row 25: MATURITY ADJUSTMENT = Grand Total x (Multiplier - 1).
A27: TOTAL SPEND | Z27: =Z23+Z24+Z25 | AB27: Row 27: TOTAL SPEND = Grand Total + CG&E + Maturity.
AB29: END-TO-END WALKTHROUGH (FAU Example)
AB30: STEP 1: Get unit count from INPUT
AB31: INPUT!B22 = 22 (governed delivery units)
AB33: STEP 2: Apply size split
AB34: Small 55%: 22 x 0.55 = 12.1 units
AB35: Medium 30%: 22 x 0.30 = 6.6 units
AB36: Large 15%: 22 x 0.15 = 3.3 units
AB38: STEP 3: Base effort (IBM-standard for FAU)
AB39: Small: 2.0 FTE-months | Medium: 4.0 | Large: 6.0
AB41: STEP 4: Learning curve (FAU = no LC)
AB42: Factor = 1.0 (learning curve only applies to AMU)
AB44: STEP 5: Effective effort = Base x LC
... AB82: TOTAL SPEND = $202,058,314

Sheet TIMELINE
A1: IBM Cybersecurity Services — Multi-Year Phasing | J1: HOW TO USE THIS SHEET
J2: PURPOSE: Distributes total program cost across 7 years. Provides annual budgets and staffing estimates.
A3: YEAR-BY-YEAR DISTRIBUTION (%) | J3: DATA FLOW: Receives: Unit totals from UNITS, CG&E% from CONFIG, Maturity from CONFIG Produces: Annual cost forecasts and peak FTE for SUMMARY sheet
A4: Unit Type | B4: Year 1 | C4: Year 2 | D4: Year 3 | E4: Year 4 | F4: Year 5 | G4: Year 6 | H4: Year 7 | I4: Total | J4: SECTION: YEAR DISTRIBUTION %
A5: FAU | B5: 0.2 | C5: 0.2 | D5: 0.2 | E5: 0.15 | F5: 0.1 | G5: 0.1 | H5: 0.05 | I5: =SUM(B5:H5) | J5: Client-editable. For each unit type, enter % of work per year. Must sum to 100%. Default patterns: FAU (governance): 20/20/20/15/10/10/5 (starts early, sustains) AMU (applications): 5/10/20/25/25/10/5 (ramps, peaks mid-program) VTU (vendors): 5/10/15/20/25/15/10 (back-loaded)
A6: NMU | B6: 0.1 | C6: 0.2 | D6: 0.25 | E6: 0.2 | F6: 0.15 | G6: 0.05 | H6: 0.05 | I6: =SUM(B6:H6)
A7: AMU | B7: 0.05 | C7: 0.1 | D7: 0.2 | E7: 0.25 | F7: 0.25 | G7: 0.1 | H7: 0.05 | I7: =SUM(B7:H7)
A8: PMU | B8: 0.1 | C8: 0.15 | D8: 0.25 | E8: 0.2 | F8: 0.15 | G8: 0.1 | H8: 0.05 | I8: =SUM(B8:H8)
A9: CMU | B9: 0.15 | C9: 0.2 | D9: 0.25 | E9: 0.2 | F9: 0.1 | G9: 0.05 | H9: 0.05 | I9: =SUM(B9:H9)
A10: DMU | B10: 0.05 | C10: 0.1 | D10: 0.15 | E10: 0.25 | F10: 0.25 | G10: 0.15 | H10: 0.05 | I10: =SUM(B10:H10)
A11: DAU | B11: 0.1 | C11: 0.2 | D11: 0.25 | E11: 0.2 | F11: 0.15 | G11: 0.05 | H11: 0.05 | I11: =SUM(B11:H11)
A12: VTU | B12: 0.05 | C12: 0.1 | D12: 0.15 | E12: 0.2 | F12: 0.25 | G12: 0.15 | H12: 0.1 | I12: =SUM(B12:H12)
A14: ANNUAL COST BY UNIT TYPE (USD) | J14: SECTION: ANNUAL COST
A15: Unit Type | B15: Year 1 | C15: Year 2 | D15: Year 3 | E15: Year 4 | F15: Year 5 | G15: Year 6 | H15: Year 7 | I15: Total | J15: Annual Cost = Unit Total x Year %. Example: AMU Year 3 = $170.9M x 20% = $34.2M
A16: FAU | B16: =(UNITS!B21+UNITS!C21+UNITS!D21)*B5 | C16: =(UNITS!B21+UNITS!C21+UNITS!D21)*C5 | D16: =(UNITS!B21+UNITS!C21+UNITS!D21)*D5 | E16: =(UNITS!B21+UNITS!C21+UNITS!D21)*E5 | F16: =(UNITS!B21+UNITS!C21+UNITS!D21)*F5 | G16: =(UNITS!B21+UNITS!C21+UNITS!D21)*G5 | H16: =(UNITS!B21+UNITS!C21+UNITS!D21)*H5 | I16: =SUM(B16:H16)
A17: NMU | B17: =(UNITS!E21+UNITS!F21+UNITS!G21)*B6 | C17: =(UNITS!E21+UNITS!F21+UNITS!G21)*C6 | D17: =(UNITS!E21+UNITS!F21+UNITS!G21)*D6 | E17: =(UNITS!E21+UNITS!F21+UNITS!G21)*E6 | F17: =(UNITS!E21+UNITS!F21+UNITS!G21)*F6 | G17: =(UNITS!E21+UNITS!F21+UNITS!G21)*G6 | H17: =(UNITS!E21+UNITS!F21+UNITS!G21)*H6 | I17: =SUM(B17:H17)
A18: AMU | B18: =(UNITS!H21+UNITS!I21+UNITS!J21)*B7 | C18: =(UNITS!H21+UNITS!I21+UNITS!J21)*C7 | D18: =(UNITS!H21+UNITS!I21+UNITS!J21)*D7 | E18: =(UNITS!H21+UNITS!I21+UNITS!J21)*E7 | F18: =(UNITS!H21+UNITS!I21+UNITS!J21)*F7 | G18: =(UNITS!H21+UNITS!I21+UNITS!J21)*G7 | H18: =(UNITS!H21+UNITS!I21+UNITS!J21)*H7 | I18: =SUM(B18:H18)
A19: PMU | B19: =(UNITS!K21+UNITS!L21+UNITS!M21)*B8 | C19: =(UNITS!K21+UNITS!L21+UNITS!M21)*C8 | D19: =(UNITS!K21+UNITS!L21+UNITS!M21)*D8 | E19: =(UNITS!K21+UNITS!L21+UNITS!M21)*E8 | F19: =(UNITS!K21+UNITS!L21+UNITS!M21)*F8 | G19: =(UNITS!K21+UNITS!L21+UNITS!M21)*G8 | H19: =(UNITS!K21+UNITS!L21+UNITS!M21)*H8 | I19: =SUM(B19:H19)
A20: CMU | B20: =(UNITS!N21+UNITS!O21+UNITS!P21)*B9 | C20: =(UNITS!N21+UNITS!O21+UNITS!P21)*C9 | D20: =(UNITS!N21+UNITS!O21+UNITS!P21)*D9 | E20: =(UNITS!N21+UNITS!O21+UNITS!P21)*E9 | F20: =(UNITS!N21+UNITS!O21+UNITS!P21)*F9 | G20: =(UNITS!N21+UNITS!O21+UNITS!P21)*G9 | H20: =(UNITS!N21+UNITS!O21+UNITS!P21)*H9 | I20: =SUM(B20:H20)
A21: DMU | B21: =(UNITS!Q21+UNITS!R21+UNITS!S21)*B10 | C21: =(UNITS!Q21+UNITS!R21+UNITS!S21)*C10 | D21: =(UNITS!Q21+UNITS!R21+UNITS!S21)*D10 | E21: =(UNITS!Q21+UNITS!R21+UNITS!S21)*E10 | F21: =(UNITS!Q21+UNITS!R21+UNITS!S21)*F10 | G21: =(UNITS!Q21+UNITS!R21+UNITS!S21)*G10 | H21: =(UNITS!Q21+UNITS!R21+UNITS!S21)*H10 | I21: =SUM(B21:H21)
A22: DAU | B22: =(UNITS!T21+UNITS!U21+UNITS!V21)*B11 | C22: =(UNITS!T21+UNITS!U21+UNITS!V21)*C11 | D22: =(UNITS!T21+UNITS!U21+UNITS!V21)*D11 | E22: =(UNITS!T21+UNITS!U21+UNITS!V21)*E11 | F22: =(UNITS!T21+UNITS!U21+UNITS!V21)*F11 | G22: =(UNITS!T21+UNITS!U21+UNITS!V21)*G11 | H22: =(UNITS!T21+UNITS!U21+UNITS!V21)*H11 | I22: =SUM(B22:H22)
A23: VTU | B23: =(UNITS!W21+UNITS!X21+UNITS!Y21)*B12 | C23: =(UNITS!W21+UNITS!X21+UNITS!Y21)*C12 | D23: =(UNITS!W21+UNITS!X21+UNITS!Y21)*D12 | E23: =(UNITS!W21+UNITS!X21+UNITS!Y21)*E12 | F23: =(UNITS!W21+UNITS!X21+UNITS!Y21)*F12 | G23: =(UNITS!W21+UNITS!X21+UNITS!Y21)*G12 | H23: =(UNITS!W21+UNITS!X21+UNITS!Y21)*H12 | I23: =SUM(B23:H23)
A24: Annual Subtotal (Units) | B24: =SUM(B16:B23) | C24: =SUM(C16:C23) | D24: =SUM(D16:D23) | E24: =SUM(E16:E23) | F24: =SUM(F16:F23) | G24: =SUM(G16:G23) | H24: =SUM(H16:H23) | I24: =SUM(B24:H24) | J24: Annual Subtotal: Sum of all 8 unit types for that year.
A25: CG&E | B25: =B24*CONFIG!B28 | C25: =C24*CONFIG!B28 | D25: =D24*CONFIG!B28 | E25: =E24*CONFIG!B28 | F25: =F24*CONFIG!B28 | G25: =G24*CONFIG!B28 | H25: =H24*CONFIG!B28 | I25: =SUM(B25:H25) | J25: CG&E: Annual subtotal x CG&E % from CONFIG.
A26: Maturity Adjustment | B26: =B24*(CONFIG!B38-1) | C26: =C24*(CONFIG!B38-1) | D26: =D24*(CONFIG!B38-1) | E26: =E24*(CONFIG!B38-1) | F26: =F24*(CONFIG!B38-1) | G26: =G24*(CONFIG!B38-1) | H26: =H24*(CONFIG!B38-1) | I26: =SUM(B26:H26) | J26: Maturity: Annual subtotal x (Multiplier - 1).
A27: ANNUAL TOTAL | B27: =B24+B25+B26 | C27: =C24+C25+C26 | D27: =D24+D25+D26 | E27: =E24+E25+E26 | F27: =F24+F25+F26 | G27: =G24+G25+G26 | H27: =H24+H25+H26 | I27: =SUM(B27:H27) | J27: ANNUAL TOTAL: Budget required for that year.
A29: STAFFING ESTIMATE | J29: SECTION: STAFFING
A30: Unit Type | B30: Year 1 | C30: Year 2 | D30: Year 3 | E30: Year 4 | F30: Year 5 | G30: Year 6 | H30: Year 7 | I30: Total | J30: Peak FTE = Annual FTE-months / 12. This is an average, not peak. Multiply by 1.25 for safe staffing.
A31: Annual Effort (FTE-months) | B31: =(UNITS!B12+UNITS!C12+UNITS!D12)*B5+(UNITS!E12+UNITS!F12+UNITS!G12)*B6+(UNITS!H12+UNITS!I12+UNITS!J12)*B7+(UNITS!K12+UNITS!L12+UNITS!M12)*B8+(UNITS!N12+UNITS!O12+UNITS!P12)*B9+(UNITS!Q12+UNITS!R12+UNITS!S12)*B10+(UNITS!T12+UNITS!U12+UNITS!V12)*B11+(UNITS!W12+UNITS!X12+UNITS!Y12)*B12 | C31: =(UNITS!B12+UNITS!C12+UNITS!D12)*C5+(UNITS!E12+UNITS!F12+UNITS!G12)*C6+(UNITS!H12+UNITS!I12+UNITS!J12)*C7+(UNITS!K12+UNITS!L12+UNITS!M12)*C8+(UNITS!N12+UNITS!O12+UNITS!P12)*C9+(UNITS!Q12+UNITS!R12+UNITS!S12)*C10+(UNITS!T12+UNITS!U12+UNITS!V12)*C11+(UNITS!W12+UNITS!X12+UNITS!Y12)*C12 | D31: =(UNITS!B12+UNITS!C12+UNITS!D12)*D5+(UNITS!E12+UNITS!F12+UNITS!G12)*D6+(UNITS!H12+UNITS!I12+UNITS!J12)*D7+(UNITS!K12+UNITS!L12+UNITS!M12)*D8+(UNITS!N12+UNITS!O12+UNITS!P12)*D9+(UNITS!Q12+UNITS!R12+UNITS!S12)*D10+(UNITS!T12+UNITS!U12+UNITS!V12)*D11+(UNITS!W12+UNITS!X12+UNITS!Y12)*D12 | E31: =(UNITS!B12+UNITS!C12+UNITS!D12)*E5+(UNITS!E12+UNITS!F12+UNITS!G12)*E6+(UNITS!H12+UNITS!I12+UNITS!J12)*E7+(UNITS!K12+UNITS!L12+UNITS!M12)*E8+(UNITS!N12+UNITS!O12+UNITS!P12)*E9+(UNITS!Q12+UNITS!R12+UNITS!S12)*E10+(UNITS!T12+UNITS!U12+UNITS!V12)*E11+(UNITS!W12+UNITS!X12+UNITS!Y12)*E12 | F31: =(UNITS!B12+UNITS!C12+UNITS!D12)*F5+(UNITS!E12+UNITS!F12+UNITS!G12)*F6+(UNITS!H12+UNITS!I12+UNITS!J12)*F7+(UNITS!K12+UNITS!L12+UNITS!M12)*F8+(UNITS!N12+UNITS!O12+UNITS!P12)*F9+(UNITS!Q12+UNITS!R12+UNITS!S12)*F10+(UNITS!T12+UNITS!U12+UNITS!V12)*F11+(UNITS!W12+UNITS!X12+UNITS!Y12)*F12 | G31: =(UNITS!B12+UNITS!C12+UNITS!D12)*G5+(UNITS!E12+UNITS!F12+UNITS!G12)*G6+(UNITS!H12+UNITS!I12+UNITS!J12)*G7+(UNITS!K12+UNITS!L12+UNITS!M12)*G8+(UNITS!N12+UNITS!O12+UNITS!P12)*G9+(UNITS!Q12+UNITS!R12+UNITS!S12)*G10+(UNITS!T12+UNITS!U12+UNITS!V12)*G11+(UNITS!W12+UNITS!X12+UNITS!Y12)*G12 | H31: =(UNITS!B12+UNITS!C12+UNITS!D12)*H5+(UNITS!E12+UNITS!F12+UNITS!G12)*H6+(UNITS!H12+UNITS!I12+UNITS!J12)*H7+(UNITS!K12+UNITS!L12+UNITS!M12)*H8+(UNITS!N12+UNITS!O12+UNITS!P12)*H9+(UNITS!Q12+UNITS!R12+UNITS!S12)*H10+(UNITS!T12+UNITS!U12+UNITS!V12)*H11+(UNITS!W12+UNITS!X12+UNITS!Y12)*H12 | I31: =SUM(B31:H31)
A32: Peak FTE (headcount estimate) | B32: =B31/12 | C32: =C31/12 | D32: =D31/12 | E32: =E31/12 | F32: =F31/12 | G32: =G31/12 | H32: =H31/12 | I32: ="N/A"
A34: Reconciliation Check | B34: =IF(ABS(I27-UNITS!Z27)<1,"OK","MISMATCH") | J34: Reconciliation: Checks sum of annual totals = UNITS TOTAL SPEND. Must show 'OK'.

Sheet SUMMARY
A1: IBM Cybersecurity Services — Executive Summary | E1: HOW TO READ THIS DASHBOARD
E2: PURPOSE: Executive-ready summary. All values auto-calculated. Present to leadership for budget approval.
A3: TOTAL PROGRAM COST | B3: =UNITS!Z27 | E3: TOTAL PROGRAM COST: The fully-loaded cost including all units, CG&E, maturity, risk, and learning curve.
A5: COST BREAKDOWN BY UNIT TYPE | E5: COST BREAKDOWN BY UNIT TYPE
A6: Unit Type | B6: Cost (USD) | C6: % of Subtotal | E6: Each unit type's total cost and % of subtotal. AMU (Application Migration) typically dominates at 80-90%.
A7: Federated Adoption Unit (FAU) | B7: =UNITS!B21+UNITS!C21+UNITS!D21 | C7: =B7/UNITS!Z23 | E7: FAU: Governance coordination. Typically <1% of total.
A8: Network / Connectivity Migration Unit (NMU) | B8: =UNITS!E21+UNITS!F21+UNITS!G21 | C8: =B8/UNITS!Z23 | E8: NMU: Network/TLS migration. Small unless many legacy zones.
A9: Application Migration Unit (AMU) | B9: =UNITS!H21+UNITS!I21+UNITS!J21 | C9: =B9/UNITS!Z23 | E9: AMU: THE BIGGEST COST DRIVER. Application-level crypto for all apps.
A10: Platform/Cloud/Runtime Migration Unit (PMU) | B10: =UNITS!K21+UNITS!L21+UNITS!M21 | C10: =B10/UNITS!Z23 | E10: PMU: Platform-level changes. Moderate cost.
A11: PKI/CLM/KMS Migration Unit (CMU) | B11: =UNITS!N21+UNITS!O21+UNITS!P21 | C11: =B11/UNITS!Z23 | E11: CMU: PKI/KMS infrastructure. High tooling (HSMs).
A12: Data & Storage Migration Unit (DMU) | B12: =UNITS!Q21+UNITS!R21+UNITS!S21 | C12: =B12/UNITS!Z23 | E12: DMU: Data re-encryption. Timeline-sensitive.
A13: DevSecOps & Automation Unit (DAU) | B13: =UNITS!T21+UNITS!U21+UNITS!V21 | C13: =B13/UNITS!Z23 | E13: DAU: CI/CD pipeline integration. Small cost, high impact.
A14: Vendor / Third-Party Unit (VTU) | B14: =UNITS!W21+UNITS!X21+UNITS!Y21 | C14: =B14/UNITS!Z23 | E14: VTU: Vendor coordination. PM-heavy.
A15: Subtotal (all units) | B15: =SUM(B7:B14)
A16: Central Governance & Enablement | B16: =UNITS!Z24
A17: Maturity Adjustment | B17: =UNITS!Z25
A18: TOTAL SPEND | B18: =B15+B16+B17
A20: ANNUAL COST FORECAST | E20: ANNUAL COST FORECAST
A21: Year | B21: Annual Cost (USD) | C21: Cumulative Cost | D21: Peak FTE | E21: Annual Cost: What's needed that year. Cumulative: Running total. Peak FTE: Average team size. Use for annual budget requests and resource planning.
A22: Year 1 | B22: =TIMELINE!B27 | C22: =B22 | D22: =TIMELINE!B32
A23: Year 2 | B23: =TIMELINE!C27 | C23: =C22+B23 | D23: =TIMELINE!C32
A24: Year 3 | B24: =TIMELINE!D27 | C24: =C23+B24 | D24: =TIMELINE!D32
A25: Year 4 | B25: =TIMELINE!E27 | C25: =C24+B25 | D25: =TIMELINE!E32
A26: Year 5 | B26: =TIMELINE!F27 | C26: =C25+B26 | D26: =TIMELINE!F32
A27: Year 6 | B27: =TIMELINE!G27 | C27: =C26+B27 | D27: =TIMELINE!G32
A28: Year 7 | B28: =TIMELINE!H27 | C28: =C27+B28 | D28: =TIMELINE!H32
A30: KEY ASSUMPTIONS & PARAMETERS | E30: KEY ASSUMPTIONS
A31: Total Applications | B31: =INPUT!B24 | E31: Critical inputs driving the estimate: Total Apps: +/-10% apps = +/-10% AMU cost Complexity: All-Low (1.0x) vs All-High (2.0x) Learning Curve: At 0.41 = 59% savings Risk: 15-25% range Maturity: Score 2.6 avg = 1.0x (no change)
A32: Complexity Multiplier | B32: =INPUT!G17
A33: Maturity Multiplier | B33: =CONFIG!B38
A34: Risk Contingency | B34: =CONFIG!B27
A35: CG&E % | B35: =CONFIG!B28
A36: AMU Learning Curve (blended factor) | B36: =UNITS!H10
A37: Average Blended FTE Rate | B37: =AVERAGE(CONFIG!G16:CONFIG!G23)
A38: Program Duration | B38: 7 years
A40: COMPLETE COST BUILD-UP: How the Total is Constructed
A41: LAYER 1: Per-Application Effort
A42: 6 app archetypes: 0.6 to 4.0 FTE-months | D42: Weighted average = 1.55 FTE-months/app
A43: Complexity multiplier (all Low = 1.0x) | D43: 1.55 x 1.0 = 1.55 FTE-months/app
A45: LAYER 2: Learning Curve (AMU only)
...
